<?xml version="1.0" encoding="utf-8" ?>
<!-- This URDF was automatically created by SolidWorks to URDF Exporter! Originally created by Stephen Brawner (brawner@gmail.com) 
     Commit Version: 1.6.0-4-g7f85cfe  Build Version: 1.6.7995.38578
     For more information, please see http://wiki.ros.org/sw_urdf_exporter -->
<robot name="yeahbot_c1">
    <link name="base_link">
        <inertial>
            <origin xyz="0.00466297153561749 -0.00153908295027716 -0.0160673413277668" rpy="0 0 0" />
            <mass value="0.00001" />
            <inertia ixx="0.00118188018234599" ixy="5.61129761635286E-06" ixz="6.76205035523336E-06" iyy="0.0016337887803542" iyz="-1.59326873297142E-06" izz="0.00237931918663682" />
        </inertial>
        <visual>
            <origin xyz="0 0 0" rpy="0 0 0" />
            <geometry>
                <mesh filename="package://yeahbot_c1/meshes/base_link.STL" />
            </geometry>
            <material name="">
                <color rgba="0.411764705882353 0.411764705882353 0.411764705882353 1" />
            </material>
        </visual>
        <collision>
            <origin xyz="0 0 0" rpy="0 0 0" />
            <geometry>
                <mesh filename="package://yeahbot_c1/meshes/base_link.STL" />
            </geometry>
        </collision>
    </link>
    <link name="wheel_lf_link">
        <inertial>
            <origin xyz="-4.84915538279118E-08 -0.00839875845441912 -4.59090557007602E-07" rpy="0 0 0" />
            <mass value="0.00001" />
            <inertia ixx="6.8397294914088E-05" ixy="1.24963769585337E-11" ixz="5.68757400846383E-10" iyy="0.000109193414887083" iyz="-5.04349519191495E-10" izz="6.84002090632343E-05" />
        </inertial>
        <visual>
            <origin xyz="0 0 0" rpy="0 0 0" />
            <geometry>
                <mesh filename="package://yeahbot_c1/meshes/wheel_lf_link.STL" />
            </geometry>
            <material name="">
                <color rgba="0.203921568627451 0.203921568627451 0.203921568627451 1" />
            </material>
        </visual>
        <collision>
            <origin xyz="0 0 0" rpy="0 0 0" />
            <geometry>
                <mesh filename="package://yeahbot_c1/meshes/wheel_lf_link.STL" />
            </geometry>
        </collision>
    </link>
    <joint name="wheel_lf_joint" type="continuous">
        <origin xyz="0.0906867232171967 0.112758694630361 -0.0334999999999999" rpy="0 0 0" />
        <parent link="base_link" />
        <child link="wheel_lf_link" />
        <axis xyz="0 1 0" />
    </joint>
    <link name="wheel_rf_link">
        <inertial>
            <origin xyz="2.35543067828026E-07 0.00839893400996694 3.48178443083935E-07" rpy="0 0 0" />
            <mass value="0.00001" />
            <inertia ixx="6.83967465049843E-05" ixy="-4.91979625838237E-10" ixz="2.9427345063431E-10" iyy="0.000109188700101397" iyz="-6.20465094945869E-10" izz="6.83967026899844E-05" />
        </inertial>
        <visual>
            <origin xyz="0 0 0" rpy="0 0 0" />
            <geometry>
                <mesh filename="package://yeahbot_c1/meshes/wheel_rf_link.STL" />
            </geometry>
            <material name="">
                <color rgba="0.149019607843137 0.149019607843137 0.149019607843137 1" />
            </material>
        </visual>
        <collision>
            <origin xyz="0 0 0" rpy="0 0 0" />
            <geometry>
                <mesh filename="package://yeahbot_c1/meshes/wheel_rf_link.STL" />
            </geometry>
        </collision>
    </link>
    <joint name="wheel_rf_joint" type="continuous">
        <origin xyz="0.0906867232171966 -0.114777457475873 -0.0335000000000006" rpy="0 0 0" />
        <parent link="base_link" />
        <child link="wheel_rf_link" />
        <axis xyz="0 1 0" />
    </joint>
    <link name="wheel_lb_link">
        <inertial>
            <origin xyz="-2.72972162623786E-07 -0.00839893236951531 -3.45282314108408E-07" rpy="0 0 0" />
            <mass value="0.00001" />
            <inertia ixx="6.83965592857652E-05" ixy="-4.67908491184818E-10" ixz="2.28982918059758E-10" iyy="0.000109188713772428" iyz="-6.41854054411003E-10" izz="6.83969236052175E-05" />
        </inertial>
        <visual>
            <origin xyz="0 0 0" rpy="0 0 0" />
            <geometry>
                <mesh filename="package://yeahbot_c1/meshes/wheel_lb_link.STL" />
            </geometry>
            <material name="">
                <color rgba="0.149019607843137 0.149019607843137 0.149019607843137 1" />
            </material>
        </visual>
        <collision>
            <origin xyz="0 0 0" rpy="0 0 0" />
            <geometry>
                <mesh filename="package://yeahbot_c1/meshes/wheel_lb_link.STL" />
            </geometry>
        </collision>
    </link>
    <joint name="wheel_lb_joint" type="continuous">
        <origin xyz="-0.0873063572631356 0.112758694630026 -0.0334999999999966" rpy="0 0 0" />
        <parent link="base_link" />
        <child link="wheel_lb_link" />
        <axis xyz="0 1 0" />
    </joint>
    <link name="wheel_rb_link">
        <inertial>
            <origin xyz="4.85118345633362E-08 0.00839875845437382 -4.59094896945733E-07" rpy="0 0 0" />
            <mass value="0.00001" />
            <inertia ixx="6.83972949244701E-05" ixy="1.25204826151774E-11" ixz="-5.68734324528353E-10" iyy="0.000109193414887782" iyz="5.04343934484521E-10" izz="6.84002090537243E-05" />
        </inertial>
        <visual>
            <origin xyz="0 0 0" rpy="0 0 0" />
            <geometry>
                <mesh filename="package://yeahbot_c1/meshes/wheel_rb_link.STL" />
            </geometry>
            <material name="">
                <color rgba="0.203921568627451 0.203921568627451 0.203921568627451 1" />
            </material>
        </visual>
        <collision>
            <origin xyz="0 0 0" rpy="0 0 0" />
            <geometry>
                <mesh filename="package://yeahbot_c1/meshes/wheel_rb_link.STL" />
            </geometry>
        </collision>
    </link>
    <joint name="wheel_rb_joint" type="continuous">
        <origin xyz="-0.0873063572631367 -0.114777457476207 -0.0335000000000006" rpy="0 0 0" />
        <parent link="base_link" />
        <child link="wheel_rb_link" />
        <axis xyz="0 1 0" />
    </joint>
    <link name="imu_link">
        <inertial>
            <origin xyz="-1.2407750220822E-05 -0.00716717740981382 -0.0103264329614115" rpy="0 0 0" />
            <mass value="0.00001" />
            <inertia ixx="9.48782215617797E-06" ixy="6.72090333991418E-09" ixz="7.80615146406528E-10" iyy="4.36544577953433E-06" iyz="5.84243702680289E-09" izz="1.33425192423164E-05" />
        </inertial>
        <visual>
            <origin xyz="0 0 0" rpy="0 0 0" />
            <geometry>
                <mesh filename="package://yeahbot_c1/meshes/imu_link.STL" />
            </geometry>
            <material name="">
                <color rgba="1 1 1 1" />
            </material>
        </visual>
        <collision>
            <origin xyz="0 0 0" rpy="0 0 0" />
            <geometry>
                <mesh filename="package://yeahbot_c1/meshes/imu_link.STL" />
            </geometry>
        </collision>
    </link>
    <joint name="imu_joint" type="fixed">
        <origin xyz="-0.047201 0.018594 0.033186" rpy="0 0 0" />
        <parent link="base_link" />
        <child link="imu_link" />
        <axis xyz="0 0 0" />
    </joint>
    <link name="lider_link">
        <inertial>
            <origin xyz="-0.0126557757142219 0.00286227958079444 -0.0103246095252843" rpy="0 0 0" />
            <mass value="0.00001" />
            <inertia ixx="1.24256550732977E-05" ixy="4.74742992229018E-07" ixz="2.11242416700294E-08" iyy="1.29339878785445E-05" iyz="-2.6384350040162E-08" izz="2.32000015148583E-05" />
        </inertial>
        <visual>
            <origin xyz="0 0 0" rpy="0 0 0" />
            <geometry>
                <mesh filename="package://yeahbot_c1/meshes/lider_link.STL" />
            </geometry>
            <material name="">
                <color rgba="0.4 0.4 0.4 1" />
            </material>
        </visual>
        <collision>
            <origin xyz="0 0 0" rpy="0 0 0" />
            <geometry>
                <mesh filename="package://yeahbot_c1/meshes/lider_link.STL" />
            </geometry>
        </collision>
    </link>
    <joint name="lider_joint" type="fixed">
        <origin xyz="0.084194 -0.0010094 0.0231" rpy="0 0 3.1415926" />
        <parent link="base_link" />
        <child link="lider_link" />
        <axis xyz="0 0 0" />
    </joint>
    <link name="screen_link">
        <inertial>
            <origin xyz="0.00315525424866003 0.000703583840673594 -0.00551023521150622" rpy="0 0 0" />
            <mass value="0.00001" />
            <inertia ixx="0.000374518038974213" ixy="-1.67585708743814E-06" ixz="-6.34569098559303E-05" iyy="0.00012906189525786" iyz="-1.67585708743744E-06" izz="0.000373081373994419" />
        </inertial>
        <visual>
            <origin xyz="0 0 0" rpy="0 0 0" />
            <geometry>
                <mesh filename="package://yeahbot_c1/meshes/screen_link.STL" />
            </geometry>
            <material name="">
                <color rgba="0.556862745098039 0.556862745098039 0.556862745098039 1" />
            </material>
        </visual>
        <collision>
            <origin xyz="0 0 0" rpy="0 0 0" />
            <geometry>
                <mesh filename="package://yeahbot_c1/meshes/screen_link.STL" />
            </geometry>
        </collision>
    </link>
    <joint name="screen_joint" type="fixed">
        <origin xyz="-0.09573 -0.0010094 0.090967" rpy="0 0 0" />
        <parent link="base_link" />
        <child link="screen_link" />
        <axis xyz="0 0 0" />
        <limit upper="0.001" lower="-0.001" effort="100" velocity="1" />
    </joint>
    <link name="arm_0_link">
        <inertial>
            <origin xyz="2.64540739135233E-06 -5.92142325849809E-05 0.0298134396521152" rpy="0 0 0" />
            <mass value="0.00001" />
            <inertia ixx="1.30813779896253E-05" ixy="1.73866669581973E-07" ixz="-1.28481943331332E-09" iyy="8.78551361891797E-06" iyz="2.91914595152878E-08" izz="1.23126981744758E-05" />
        </inertial>
        <visual>
            <origin xyz="0 0 0" rpy="0 0 0" />
            <geometry>
                <mesh filename="package://yeahbot_c1/meshes/arm_0_link.STL" />
            </geometry>
            <material name="">
                <color rgba="0.149019607843137 0.149019607843137 0.149019607843137 1" />
            </material>
        </visual>
        <collision>
            <origin xyz="0 0 0" rpy="0 0 0" />
            <geometry>
                <mesh filename="package://yeahbot_c1/meshes/arm_0_link.STL" />
            </geometry>
        </collision>
    </link>
    <joint name="arm_0_joint" type="revolute">
        <origin xyz="0.0171436427368627 -0.00100938142292312 0.076498679980641" rpy="0 0 0" />
        <parent link="base_link" />
        <child link="arm_0_link" />
        <axis xyz="0 0 -1" />
        <limit upper="2.355" lower="-2.355" effort="100" velocity="1" />
        <safety_controller soft_upper_limit="2.334" soft_lower_limit="-2.334" k_position="100.0" k_velocity="40.0" />
    </joint>
    <link name="arm_1_link">
        <inertial>
            <origin xyz="-0.000864434271694619 0.02146953748423 0.0637686604465789" rpy="0 0 0" />
            <mass value="0.00001" />
            <inertia ixx="1.67705261573249E-05" ixy="2.58559765959361E-07" ixz="-4.17326201657409E-10" iyy="1.03959973011344E-05" iyz="-1.68995737298452E-11" izz="1.14198194083269E-05" />
        </inertial>
        <visual>
            <origin xyz="0 0 0" rpy="0 0 0" />
            <geometry>
                <mesh filename="package://yeahbot_c1/meshes/arm_1_link.STL" />
            </geometry>
            <material name="">
                <color rgba="1 1 1 1" />
            </material>
        </visual>
        <collision>
            <origin xyz="0 0 0" rpy="0 0 0" />
            <geometry>
                <mesh filename="package://yeahbot_c1/meshes/arm_1_link.STL" />
            </geometry>
        </collision>
    </link>
    <joint name="arm_1_joint" type="revolute">
        <origin xyz="0.00075831 -0.02253 0.055402" rpy="0 0 0" />
        <parent link="arm_0_link" />
        <child link="arm_1_link" />
        <axis xyz="-0.040462 0.99918 0" />
        <limit upper="1.57" lower="-1.57" effort="100" velocity="1" />
        <safety_controller soft_upper_limit="1.56" soft_lower_limit="-1.56" k_position="100.0" k_velocity="40.0" />
    </joint>
    <link name="arm_2_link">
        <inertial>
            <origin xyz="-0.00188076040306438 0.02238954536478 0.0610264321329397" rpy="0 0 0" />
            <mass value="0.00001" />
            <inertia ixx="3.02797659905238E-05" ixy="3.915985169833E-07" ixz="-9.03500051211513E-10" iyy="2.06251890404292E-05" iyz="-3.66460396047082E-11" izz="1.48987493885553E-05" />
        </inertial>
        <visual>
            <origin xyz="0 0 0" rpy="0 0 0" />
            <geometry>
                <mesh filename="package://yeahbot_c1/meshes/arm_2_link.STL" />
            </geometry>
            <material name="">
                <color rgba="0.250980392156863 0.250980392156863 0.250980392156863 1" />
            </material>
        </visual>
        <collision>
            <origin xyz="0 0 0" rpy="0 0 0" />
            <geometry>
                <mesh filename="package://yeahbot_c1/meshes/arm_2_link.STL" />
            </geometry>
        </collision>
    </link>
    <joint name="arm_2_joint" type="revolute">
        <origin xyz="0 2.17314038244432E-05 0.121999692071004" rpy="0 0 0" />
        <parent link="arm_1_link" />
        <child link="arm_2_link" />
        <axis xyz="-0.0404617166748694 0.999181089434604 0" />
        <limit upper="2.355" lower="-2.355" effort="100" velocity="1" />
        <safety_controller soft_upper_limit="2.354" soft_lower_limit="-2.354" k_position="100.0" k_velocity="40.0" />
    </joint>
    <link name="arm_3_link">
        <inertial>
            <origin xyz="0.00677582697294629 0.022197827895528 0.0377802445407594" rpy="0 0 0" />
            <mass value="0.00001" />
            <inertia ixx="1.05724794844654E-05" ixy="-8.31736104157747E-08" ixz="-5.11027759460216E-07" iyy="1.26193895361522E-05" iyz="-2.03129840123352E-08" izz="7.54665305491525E-06" />
        </inertial>
        <visual>
            <origin xyz="0 0 0" rpy="0 0 0" />
            <geometry>
                <mesh filename="package://yeahbot_c1/meshes/arm_3_link.STL" />
            </geometry>
            <material name="">
                <color rgba="1 1 1 1" />
            </material>
        </visual>
        <collision>
            <origin xyz="0 0 0" rpy="0 0 0" />
            <geometry>
                <mesh filename="package://yeahbot_c1/meshes/arm_3_link.STL" />
            </geometry>
        </collision>
    </link>
    <joint name="arm_3_joint" type="revolute">
        <origin xyz="-0.000301372338149333 -1.22040361696385E-05 0.122052711964282" rpy="0 0 0" />
        <parent link="arm_2_link" />
        <child link="arm_3_link" />
        <axis xyz="-0.0404617166748562 0.999181089434605 0" />
        <limit upper="2.355" lower="-2.355" effort="100" velocity="1" />
        <safety_controller soft_upper_limit="2.354" soft_lower_limit="-2.354" k_position="100.0" k_velocity="40.0" />
    </joint>
    <link name="arm_4_link">
        <inertial>
            <origin xyz="0.0175777117200263 -0.00272690109291007 0.02720103571689" rpy="0 0 0" />
            <mass value="0.00001" />
            <inertia ixx="6.75965372004822E-06" ixy="-4.29279809576458E-08" ixz="2.93456117066075E-10" iyy="5.81713909915585E-06" iyz="2.84969552734961E-10" izz="9.49584837880932E-06" />
        </inertial>
        <visual>
            <origin xyz="0 0 0" rpy="0 0 0" />
            <geometry>
                <mesh filename="package://yeahbot_c1/meshes/arm_4_link.STL" />
            </geometry>
            <material name="">
                <color rgba="1 1 1 1" />
            </material>
        </visual>
        <collision>
            <origin xyz="0 0 0" rpy="0 0 0" />
            <geometry>
                <mesh filename="package://yeahbot_c1/meshes/arm_4_link.STL" />
            </geometry>
        </collision>
    </link>
    <joint name="arm_4_joint" type="revolute">
        <origin xyz="-0.000894941000487096 0.0222319951665307 0.0684999997921247" rpy="0 0 0" />
        <parent link="arm_3_link" />
        <child link="arm_4_link" />
        <axis xyz="-7.78422704402624E-05 0 -0.999999996965322" />
        <limit upper="2.355" lower="-2.355" effort="100" velocity="1" />
        <safety_controller soft_upper_limit="2.354" soft_lower_limit="-2.354" k_position="100.0" k_velocity="40.0" />
    </joint>
    <link name="arm_5_1_link">
        <inertial>
            <origin xyz="-0.00160262284509918 -0.00429604485499235 0.00440198912673778" rpy="0 0 0" />
            <mass value="0.00001" />
            <inertia ixx="4.17734148821274E-07" ixy="8.95225444653113E-09" ixz="-4.9338486611091E-09" iyy="1.97259661738663E-07" iyz="1.21483538585703E-07" izz="2.33581459815122E-07" />
        </inertial>
        <visual>
            <origin xyz="0 0 0" rpy="0 0 0" />
            <geometry>
                <mesh filename="package://yeahbot_c1/meshes/arm_5_1_link.STL" />
            </geometry>
            <material name="">
                <color rgba="1 1 1 1" />
            </material>
        </visual>
        <collision>
            <origin xyz="0 0 0" rpy="0 0 0" />
            <geometry>
                <mesh filename="package://yeahbot_c1/meshes/arm_5_1_link.STL" />
            </geometry>
        </collision>
    </link>
    <joint name="arm_5_1_joint" type="revolute">
        <origin xyz="-0.0021891808786022 -0.0138499198621541 0.0285002141552063" rpy="0 0 0" />
        <parent link="arm_4_link" />
        <child link="arm_5_1_link" />
        <axis xyz="0.999181086402419 0.0404617165518926 -7.79060685413583E-05" />
        <limit upper="1.57" lower="-1.57" effort="100" velocity="1" />
        <safety_controller soft_upper_limit="1.56" soft_lower_limit="-1.56" k_position="100.0" k_velocity="40.0" />
    </joint>
    <link name="arm_5_2_link">
        <inertial>
            <origin xyz="0.00653099313160226 0.00716807478922349 0.0222068880146291" rpy="0 0 0" />
            <mass value="0.00001" />
            <inertia ixx="7.64237310321007E-07" ixy="1.75342424891521E-09" ixz="5.67356860618983E-09" iyy="7.20735579801308E-07" iyz="-1.41446023443026E-07" izz="6.82810861878355E-08" />
        </inertial>
        <visual>
            <origin xyz="0 0 0" rpy="0 0 0" />
            <geometry>
                <mesh filename="package://yeahbot_c1/meshes/arm_5_2_link.STL" />
            </geometry>
            <material name="">
                <color rgba="0.180392156862745 0.180392156862745 0.180392156862745 1" />
            </material>
        </visual>
        <collision>
            <origin xyz="0 0 0" rpy="0 0 0" />
            <geometry>
                <mesh filename="package://yeahbot_c1/meshes/arm_5_2_link.STL" />
            </geometry>
        </collision>
    </link>
    <joint name="arm_5_2_joint" type="revolute">
        <origin xyz="-0.00413261493204241 -0.0220059105799439 0.0205882043789182" rpy="0 0 0" />
        <parent link="arm_5_1_link" />
        <child link="arm_5_2_link" />
        <axis xyz="-0.999181086402419 -0.0404617165519045 7.79060685561991E-05" />
        <limit upper="1.57" lower="-1.57" effort="100" velocity="1" />
        <safety_controller soft_upper_limit="1.56" soft_lower_limit="-1.56" k_position="100.0" k_velocity="40.0" />
    </joint>
    <link name="arm_5_3_link">
        <inertial>
            <origin xyz="-0.00289032468499561 0.00551105950030384 0.00631869105602889" rpy="0 0 0" />
            <mass value="0.00001" />
            <inertia ixx="3.87627948376143E-07" ixy="8.01481427459434E-09" ixz="5.06595741707943E-09" iyy="1.89788865478188E-07" iyz="-1.25450232911833E-07" izz="2.06681858311181E-07" />
        </inertial>
        <visual>
            <origin xyz="0 0 0" rpy="0 0 0" />
            <geometry>
                <mesh filename="package://yeahbot_c1/meshes/arm_5_3_link.STL" />
            </geometry>
            <material name="">
                <color rgba="0.180392156862745 0.180392156862745 0.180392156862745 1" />
            </material>
        </visual>
        <collision>
            <origin xyz="0 0 0" rpy="0 0 0" />
            <geometry>
                <mesh filename="package://yeahbot_c1/meshes/arm_5_3_link.STL" />
            </geometry>
        </collision>
    </link>
    <joint name="arm_5_3_joint" type="revolute">
        <origin xyz="-0.00305208281555558 0.0136376755264365 0.0285001946786941" rpy="0 0 0" />
        <parent link="arm_4_link" />
        <child link="arm_5_3_link" />
        <axis xyz="0.999181086402419 0.0404617165519009 -7.79060685332649E-05" />
        <limit upper="1.57" lower="-1.57" effort="100" velocity="0" />
    </joint>
    <link name="arm_5_4_link">
        <inertial>
            <origin xyz="0.00708876952486796 -0.00660591735410168 0.022210183026377" rpy="0 0 0" />
            <mass value="0.00001" />
            <inertia ixx="7.64235750176141E-07" ixy="1.7699187699163E-09" ixz="-5.76932183362275E-09" iyy="7.20872335496583E-07" iyz="1.41129955606625E-07" izz="6.81458906374227E-08" />
        </inertial>
        <visual>
            <origin xyz="0 0 0" rpy="0 0 0" />
            <geometry>
                <mesh filename="package://yeahbot_c1/meshes/arm_5_4_link.STL" />
            </geometry>
            <material name="">
                <color rgba="0.180392156862745 0.180392156862745 0.180392156862745 1" />
            </material>
        </visual>
        <collision>
            <origin xyz="0 0 0" rpy="0 0 0" />
            <geometry>
                <mesh filename="package://yeahbot_c1/meshes/arm_5_4_link.STL" />
            </geometry>
        </collision>
    </link>
    <joint name="arm_5_4_joint" type="revolute">
        <origin xyz="-0.00611590852599798 0.0207933807685759 0.0214013284882465" rpy="0 0 0" />
        <parent link="arm_5_3_link" />
        <child link="arm_5_4_link" />
        <axis xyz="-0.999181086402419 -0.0404617165518986 7.79060685375041E-05" />
        <limit upper="1.57" lower="-1.57" effort="100" velocity="1" />
        <safety_controller soft_upper_limit="1.56" soft_lower_limit="-1.56" k_position="100.0" k_velocity="40.0" />
    </joint>
    <link name="arm_5_5_link">
        <inertial>
            <origin xyz="-0.00342585543864939 0.0104759851238435 0.010607414868976" rpy="0 0 0" />
            <mass value="0.00001" />
            <inertia ixx="5.32854965242162E-08" ixy="1.06382625458393E-09" ixz="1.04279049335466E-09" iyy="2.70081778660431E-08" iyz="-2.5801941411737E-08" izz="2.69595367229415E-08" />
        </inertial>
        <visual>
            <origin xyz="0 0 0" rpy="0 0 0" />
            <geometry>
                <mesh filename="package://yeahbot_c1/meshes/arm_5_5_link.STL" />
            </geometry>
            <material name="">
                <color rgba="0.180392156862745 0.180392156862745 0.180392156862745 1" />
            </material>
        </visual>
        <collision>
            <origin xyz="0 0 0" rpy="0 0 0" />
            <geometry>
                <mesh filename="package://yeahbot_c1/meshes/arm_5_5_link.STL" />
            </geometry>
        </collision>
    </link>
    <joint name="arm_5_5_joint" type="revolute">
        <origin xyz="-0.00265602423256834 0.00389572294870971 0.0485001946179983" rpy="0 0 0" />
        <parent link="arm_4_link" />
        <child link="arm_5_5_link" />
        <axis xyz="0.999181086402419 0.0404617165519009 -7.79060685332649E-05" />
        <limit upper="1.57" lower="-1.57" effort="100" velocity="1" />
        <safety_controller soft_upper_limit="1.56" soft_lower_limit="-1.56" k_position="100.0" k_velocity="40.0" />
    </joint>
    <link name="arm_5_6_link">
        <inertial>
            <origin xyz="-0.00255168188848751 -0.011112064099651 0.0101985759294265" rpy="0 0 0" />
            <mass value="0.00001" />
            <inertia ixx="5.32819751753927E-08" ixy="1.14676663292464E-09" ixz="-1.04376151830674E-09" iyy="2.50592256648526E-08" iyz="2.57281367230067E-08" izz="2.89120102729558E-08" />
        </inertial>
        <visual>
            <origin xyz="0 0 0" rpy="0 0 0" />
            <geometry>
                <mesh filename="package://yeahbot_c1/meshes/arm_5_6_link.STL" />
            </geometry>
            <material name="">
                <color rgba="0.180392156862745 0.180392156862745 0.180392156862745 1" />
            </material>
        </visual>
        <collision>
            <origin xyz="0 0 0" rpy="0 0 0" />
            <geometry>
                <mesh filename="package://yeahbot_c1/meshes/arm_5_6_link.STL" />
            </geometry>
        </collision>
    </link>
    <joint name="arm_5_6_joint" type="revolute">
        <origin xyz="-0.00233233049917082 -0.00409772576676704 0.0485001946179963" rpy="0 0 0" />
        <parent link="arm_4_link" />
        <child link="arm_5_6_link" />
        <axis xyz="0.999181086402419 0.0404617165519009 -7.79060685332649E-05" />
        <limit upper="1.57" lower="-1.57" effort="100" velocity="1" />
        <safety_controller soft_upper_limit="1.56" soft_lower_limit="-1.56" k_position="100.0" k_velocity="40.0" />
    </joint>
    <link name="camera_link">
        <inertial>
            <origin xyz="0.00930181139625479 0.000570017906176223 -0.0171981816682287" rpy="0 0 0" />
            <mass value="0.00001" />
            <inertia ixx="2.01503074951674E-06" ixy="1.06358183075237E-08" ixz="2.62434042592078E-07" iyy="1.96107242142106E-06" iyz="2.45175134794269E-08" izz="2.70052014373521E-06" />
        </inertial>
        <visual>
            <origin xyz="0 0 0" rpy="0 0 0" />
            <geometry>
                <mesh filename="package://yeahbot_c1/meshes/camera_link.STL" />
            </geometry>
            <material name="">
                <color rgba="1 1 1 1" />
            </material>
        </visual>
        <collision>
            <origin xyz="0 0 0" rpy="0 0 0" />
            <geometry>
                <mesh filename="package://yeahbot_c1/meshes/camera_link.STL" />
            </geometry>
        </collision>
    </link>
    <joint name="camera_joint" type="fixed">
        <origin xyz="-0.0478558866618534 0.0203303173843782 0.0757670613553036" rpy="0 0 0" />
        <parent link="arm_3_link" />
        <child link="camera_link" />
        <axis xyz="0 0 0" />
    </joint>
    <transmission name="trans_wheel_lf_joint">
        <type>transmission_interface/SimpleTransmission</type>
        <joint name="wheel_lf_joint">
            <hardwareInterface>hardware_interface/EffortJointInterface</hardwareInterface>
        </joint>
        <actuator name="wheel_lf_joint_motor">
            <hardwareInterface>hardware_interface/EffortJointInterface</hardwareInterface>
            <mechanicalReduction>1</mechanicalReduction>
        </actuator>
    </transmission>
    <transmission name="trans_wheel_rf_joint">
        <type>transmission_interface/SimpleTransmission</type>
        <joint name="wheel_rf_joint">
            <hardwareInterface>hardware_interface/EffortJointInterface</hardwareInterface>
        </joint>
        <actuator name="wheel_rf_joint_motor">
            <hardwareInterface>hardware_interface/EffortJointInterface</hardwareInterface>
            <mechanicalReduction>1</mechanicalReduction>
        </actuator>
    </transmission>
    <transmission name="trans_wheel_lb_joint">
        <type>transmission_interface/SimpleTransmission</type>
        <joint name="wheel_lb_joint">
            <hardwareInterface>hardware_interface/EffortJointInterface</hardwareInterface>
        </joint>
        <actuator name="wheel_lb_joint_motor">
            <hardwareInterface>hardware_interface/EffortJointInterface</hardwareInterface>
            <mechanicalReduction>1</mechanicalReduction>
        </actuator>
    </transmission>
    <transmission name="trans_wheel_rb_joint">
        <type>transmission_interface/SimpleTransmission</type>
        <joint name="wheel_rb_joint">
            <hardwareInterface>hardware_interface/EffortJointInterface</hardwareInterface>
        </joint>
        <actuator name="wheel_rb_joint_motor">
            <hardwareInterface>hardware_interface/EffortJointInterface</hardwareInterface>
            <mechanicalReduction>1</mechanicalReduction>
        </actuator>
    </transmission>
    <transmission name="trans_arm_0_joint">
        <type>transmission_interface/SimpleTransmission</type>
        <joint name="arm_0_joint">
            <hardwareInterface>hardware_interface/EffortJointInterface</hardwareInterface>
        </joint>
        <actuator name="arm_0_joint_motor">
            <hardwareInterface>hardware_interface/EffortJointInterface</hardwareInterface>
            <mechanicalReduction>1</mechanicalReduction>
        </actuator>
    </transmission>
    <transmission name="trans_arm_1_joint">
        <type>transmission_interface/SimpleTransmission</type>
        <joint name="arm_1_joint">
            <hardwareInterface>hardware_interface/EffortJointInterface</hardwareInterface>
        </joint>
        <actuator name="arm_1_joint_motor">
            <hardwareInterface>hardware_interface/EffortJointInterface</hardwareInterface>
            <mechanicalReduction>1</mechanicalReduction>
        </actuator>
    </transmission>
    <transmission name="trans_arm_2_joint">
        <type>transmission_interface/SimpleTransmission</type>
        <joint name="arm_2_joint">
            <hardwareInterface>hardware_interface/EffortJointInterface</hardwareInterface>
        </joint>
        <actuator name="arm_2_joint_motor">
            <hardwareInterface>hardware_interface/EffortJointInterface</hardwareInterface>
            <mechanicalReduction>1</mechanicalReduction>
        </actuator>
    </transmission>
    <transmission name="trans_arm_3_joint">
        <type>transmission_interface/SimpleTransmission</type>
        <joint name="arm_3_joint">
            <hardwareInterface>hardware_interface/EffortJointInterface</hardwareInterface>
        </joint>
        <actuator name="arm_3_joint_motor">
            <hardwareInterface>hardware_interface/EffortJointInterface</hardwareInterface>
            <mechanicalReduction>1</mechanicalReduction>
        </actuator>
    </transmission>
    <transmission name="trans_arm_4_joint">
        <type>transmission_interface/SimpleTransmission</type>
        <joint name="arm_4_joint">
            <hardwareInterface>hardware_interface/EffortJointInterface</hardwareInterface>
        </joint>
        <actuator name="arm_4_joint_motor">
            <hardwareInterface>hardware_interface/EffortJointInterface</hardwareInterface>
            <mechanicalReduction>1</mechanicalReduction>
        </actuator>
    </transmission>
    <transmission name="trans_arm_5_1_joint">
        <type>transmission_interface/SimpleTransmission</type>
        <joint name="arm_5_1_joint">
            <hardwareInterface>hardware_interface/EffortJointInterface</hardwareInterface>
        </joint>
        <actuator name="arm_5_1_joint_motor">
            <hardwareInterface>hardware_interface/EffortJointInterface</hardwareInterface>
            <mechanicalReduction>1</mechanicalReduction>
        </actuator>
    </transmission>
    <transmission name="trans_arm_5_2_joint">
        <type>transmission_interface/SimpleTransmission</type>
        <joint name="arm_5_2_joint">
            <hardwareInterface>hardware_interface/EffortJointInterface</hardwareInterface>
        </joint>
        <actuator name="arm_5_2_joint_motor">
            <hardwareInterface>hardware_interface/EffortJointInterface</hardwareInterface>
            <mechanicalReduction>1</mechanicalReduction>
        </actuator>
    </transmission>
    <transmission name="trans_arm_5_3_joint">
        <type>transmission_interface/SimpleTransmission</type>
        <joint name="arm_5_3_joint">
            <hardwareInterface>hardware_interface/EffortJointInterface</hardwareInterface>
        </joint>
        <actuator name="arm_5_3_joint_motor">
            <hardwareInterface>hardware_interface/EffortJointInterface</hardwareInterface>
            <mechanicalReduction>1</mechanicalReduction>
        </actuator>
    </transmission>
    <transmission name="trans_arm_5_4_joint">
        <type>transmission_interface/SimpleTransmission</type>
        <joint name="arm_5_4_joint">
            <hardwareInterface>hardware_interface/EffortJointInterface</hardwareInterface>
        </joint>
        <actuator name="arm_5_4_joint_motor">
            <hardwareInterface>hardware_interface/EffortJointInterface</hardwareInterface>
            <mechanicalReduction>1</mechanicalReduction>
        </actuator>
    </transmission>
    <transmission name="trans_arm_5_5_joint">
        <type>transmission_interface/SimpleTransmission</type>
        <joint name="arm_5_5_joint">
            <hardwareInterface>hardware_interface/EffortJointInterface</hardwareInterface>
        </joint>
        <actuator name="arm_5_5_joint_motor">
            <hardwareInterface>hardware_interface/EffortJointInterface</hardwareInterface>
            <mechanicalReduction>1</mechanicalReduction>
        </actuator>
    </transmission>
    <transmission name="trans_arm_5_6_joint">
        <type>transmission_interface/SimpleTransmission</type>
        <joint name="arm_5_6_joint">
            <hardwareInterface>hardware_interface/EffortJointInterface</hardwareInterface>
        </joint>
        <actuator name="arm_5_6_joint_motor">
            <hardwareInterface>hardware_interface/EffortJointInterface</hardwareInterface>
            <mechanicalReduction>1</mechanicalReduction>
        </actuator>
    </transmission>
    <gazebo>
        <plugin name="gazebo_ros_control" filename="libgazebo_ros_control.so">
            <robotNamespace>/</robotNamespace>
        </plugin>
    </gazebo>
</robot>
